Workbook

Sheet Summary
A6: Total production [ds-059359__custom_19409157]
A7: Open product page | B7: Open in Data Browser
A8: Description: | B8: -
A10: Last update of data: | D10: 27/11/2025 11:00
A11: Last change of data structure: | D11: 27/11/2025 11:00
B13: Institutional source(s)
C14: Eurostat
B15: Contents | C15: PRODUCT [PRODUCT] | D15: INDICATORS
B16: Sheet 1 | C16: Demand (own calculation)
B17: Sheet 2 | C17: Methanol (methyl alcohol) [20142210] | D17: Actual production quantity
B18: Sheet 3 | C18: Methanol (methyl alcohol) [20142210] | D18: Exports quantity
B19: Sheet 4 | C19: Methanol (methyl alcohol) [20142210] | D19: Imports quantity
B20: Sheet 5 | C20: Methanol (methyl alcohol) [20142210] | D20: Quantity unit

Sheet Approach
B2: Approach:
B3: Source Total Production: https://ec.europa.eu/eurostat/databrowser/view/ds-059359__custom_19409157/default/table
B4: Source Import Export: https://ec.europa.eu/eurostat/databrowser/view/ds-059358__custom_19409204/default/table
B5: Customise your dataset:
B6: - Product: Methanol (methyl alcohol)
B7: - Indicators Total Production: Actual production quantity, Quantity unit
B8: - Indicators Import Export: Imports quantity, Exports quantity, Quantity unit
B9: - Reporter: Only consider countries which has been used for the modelling
B10: - Analyse Demand: Demand = Actual prodution quantity + Imports quantity - Exports quantity
B11: - Source methodology: | D11: eurostat

Sheet Demand
A2: PRODUCT [PRODUCT] | C2: Methanol (methyl alcohol) [20142210]
A3: INDICATORS | C3: Demand (own calcullation)
A5: TIME | B5: 2014 | C5: 2015 | D5: 2016 | E5: 2017 | F5: 2018 | G5: 2019 | H5: 2020 | I5: 2021 | J5: 2022 | K5: 2023 | L5: 2024
A6: FREQ (Labels) | B6: Annual | C6: Annual | D6: Annual | E6: Annual | F6: Annual | G6: Annual | H6: Annual | I6: Annual | J6: Annual | K6: Annual | L6: Annual
A7: REPORTER (Labels)
A8: AL | B8: =MAX(0,IF(Production!B11=":",0,Production!B11)+IF(Import!B11=":",0,Import!B11)-IF(Export!B11=":",0,Export!B11)) -> 0 | C8: =MAX(0,IF(Production!C11=":",0,Production!C11)+IF(Import!C11=":",0,Import!C11)-IF(Export!C11=":",0,Export!C11)) -> 0 | D8: =MAX(0,IF(Production!D11=":",0,Production!D11)+IF(Import!D11=":",0,Import!D11)-IF(Export!D11=":",0,Export!D11)) -> 0 | E8: =MAX(0,IF(Production!E11=":",0,Production!E11)+IF(Import!E11=":",0,Import!E11)-IF(Export!E11=":",0,Export!E11)) -> 0 | F8: =MAX(0,IF(Production!F11=":",0,Production!F11)+IF(Import!F11=":",0,Import!F11)-IF(Export!F11=":",0,Export!F11)) -> 0 | G8: =MAX(0,IF(Production!G11=":",0,Production!G11)+IF(Import!G11=":",0,Import!G11)-IF(Export!G11=":",0,Export!G11)) -> 0 | H8: =MAX(0,IF(Production!H11=":",0,Production!H11)+IF(Import!H11=":",0,Import!H11)-IF(Export!H11=":",0,Export!H11)) -> 0 | I8: =MAX(0,IF(Production!I11=":",0,Production!I11)+IF(Import!I11=":",0,Import!I11)-IF(Export!I11=":",0,Export!I11)) -> 0 | ... L8: =MAX(0,IF(Production!L11=":",0,Production!L11)+IF(Import!L11=":",0,Import!L11)-IF(Export!L11=":",0,Export!L11)) -> 0
A9: AT | B9: =MAX(0,IF(Production!B12=":",0,Production!B12)+IF(Import!B12=":",0,Import!B12)-IF(Export!B12=":",0,Export!B12)) -> 188374200 | C9: =MAX(0,IF(Production!C12=":",0,Production!C12)+IF(Import!C12=":",0,Import!C12)-IF(Export!C12=":",0,Export!C12)) -> 229971400 | D9: =MAX(0,IF(Production!D12=":",0,Production!D12)+IF(Import!D12=":",0,Import!D12)-IF(Export!D12=":",0,Export!D12)) -> 257548400 | E9: =MAX(0,IF(Production!E12=":",0,Production!E12)+IF(Import!E12=":",0,Import!E12)-IF(Export!E12=":",0,Export!E12)) -> 226499100 | F9: =MAX(0,IF(Production!F12=":",0,Production!F12)+IF(Import!F12=":",0,Import!F12)-IF(Export!F12=":",0,Export!F12)) -> 253075100 | G9: =MAX(0,IF(Production!G12=":",0,Production!G12)+IF(Import!G12=":",0,Import!G12)-IF(Export!G12=":",0,Export!G12)) -> 230592900 | H9: =MAX(0,IF(Production!H12=":",0,Production!H12)+IF(Import!H12=":",0,Import!H12)-IF(Export!H12=":",0,Export!H12)) -> 203142207 | I9: =MAX(0,IF(Production!I12=":",0,Production!I12)+IF(Import!I12=":",0,Import!I12)-IF(Export!I12=":",0,Export!I12)) -> 275568889 | ... L9: =MAX(0,IF(Production!L12=":",0,Production!L12)+IF(Import!L12=":",0,Import!L12)-IF(Export!L12=":",0,Export!L12)) -> 138736347
A10: BA | B10: =MAX(0,IF(Production!B13=":",0,Production!B13)+IF(Import!B13=":",0,Import!B13)-IF(Export!B13=":",0,Export!B13)) -> 0 | C10: =MAX(0,IF(Production!C13=":",0,Production!C13)+IF(Import!C13=":",0,Import!C13)-IF(Export!C13=":",0,Export!C13)) -> 0 | D10: =MAX(0,IF(Production!D13=":",0,Production!D13)+IF(Import!D13=":",0,Import!D13)-IF(Export!D13=":",0,Export!D13)) -> 0 | E10: =MAX(0,IF(Production!E13=":",0,Production!E13)+IF(Import!E13=":",0,Import!E13)-IF(Export!E13=":",0,Export!E13)) -> 0 | F10: =MAX(0,IF(Production!F13=":",0,Production!F13)+IF(Import!F13=":",0,Import!F13)-IF(Export!F13=":",0,Export!F13)) -> 0 | G10: =MAX(0,IF(Production!G13=":",0,Production!G13)+IF(Import!G13=":",0,Import!G13)-IF(Export!G13=":",0,Export!G13)) -> 0 | H10: =MAX(0,IF(Production!H13=":",0,Production!H13)+IF(Import!H13=":",0,Import!H13)-IF(Export!H13=":",0,Export!H13)) -> 0 | I10: =MAX(0,IF(Production!I13=":",0,Production!I13)+IF(Import!I13=":",0,Import!I13)-IF(Export!I13=":",0,Export!I13)) -> 0 | ... L10: =MAX(0,IF(Production!L13=":",0,Production!L13)+IF(Import!L13=":",0,Import!L13)-IF(Export!L13=":",0,Export!L13)) -> 0
A11: BE | B11: =MAX(0,IF(Production!B14=":",0,Production!B14)+IF(Import!B14=":",0,Import!B14)-IF(Export!B14=":",0,Export!B14)) -> 555273630 | C11: =MAX(0,IF(Production!C14=":",0,Production!C14)+IF(Import!C14=":",0,Import!C14)-IF(Export!C14=":",0,Export!C14)) -> 488054088 | D11: =MAX(0,IF(Production!D14=":",0,Production!D14)+IF(Import!D14=":",0,Import!D14)-IF(Export!D14=":",0,Export!D14)) -> 533656849 | E11: =MAX(0,IF(Production!E14=":",0,Production!E14)+IF(Import!E14=":",0,Import!E14)-IF(Export!E14=":",0,Export!E14)) -> 538554600 | F11: =MAX(0,IF(Production!F14=":",0,Production!F14)+IF(Import!F14=":",0,Import!F14)-IF(Export!F14=":",0,Export!F14)) -> 593777067 | G11: =MAX(0,IF(Production!G14=":",0,Production!G14)+IF(Import!G14=":",0,Import!G14)-IF(Export!G14=":",0,Export!G14)) -> 513664800 | H11: =MAX(0,IF(Production!H14=":",0,Production!H14)+IF(Import!H14=":",0,Import!H14)-IF(Export!H14=":",0,Export!H14)) -> 552367493 | I11: =MAX(0,IF(Production!I14=":",0,Production!I14)+IF(Import!I14=":",0,Import!I14)-IF(Export!I14=":",0,Export!I14)) -> 691392847 | ... L11: =MAX(0,IF(Production!L14=":",0,Production!L14)+IF(Import!L14=":",0,Import!L14)-IF(Export!L14=":",0,Export!L14)) -> 492417484
A12: BG | B12: =MAX(0,IF(Production!B15=":",0,Production!B15)+IF(Import!B15=":",0,Import!B15)-IF(Export!B15=":",0,Export!B15)) -> 26315100 | C12: =MAX(0,IF(Production!C15=":",0,Production!C15)+IF(Import!C15=":",0,Import!C15)-IF(Export!C15=":",0,Export!C15)) -> 29571500 | D12: =MAX(0,IF(Production!D15=":",0,Production!D15)+IF(Import!D15=":",0,Import!D15)-IF(Export!D15=":",0,Export!D15)) -> 26141700 | E12: =MAX(0,IF(Production!E15=":",0,Production!E15)+IF(Import!E15=":",0,Import!E15)-IF(Export!E15=":",0,Export!E15)) -> 24745500 | F12: =MAX(0,IF(Production!F15=":",0,Production!F15)+IF(Import!F15=":",0,Import!F15)-IF(Export!F15=":",0,Export!F15)) -> 37901200 | G12: =MAX(0,IF(Production!G15=":",0,Production!G15)+IF(Import!G15=":",0,Import!G15)-IF(Export!G15=":",0,Export!G15)) -> 41281100 | H12: =MAX(0,IF(Production!H15=":",0,Production!H15)+IF(Import!H15=":",0,Import!H15)-IF(Export!H15=":",0,Export!H15)) -> 36467225 | I12: =MAX(0,IF(Production!I15=":",0,Production!I15)+IF(Import!I15=":",0,Import!I15)-IF(Export!I15=":",0,Export!I15)) -> 38657871 | ... L12: =MAX(0,IF(Production!L15=":",0,Production!L15)+IF(Import!L15=":",0,Import!L15)-IF(Export!L15=":",0,Export!L15)) -> 66053043
A13: CZ | B13: =MAX(0,IF(Production!B16=":",0,Production!B16)+IF(Import!B16=":",0,Import!B16)-IF(Export!B16=":",0,Export!B16)) -> 98060800 | C13: =MAX(0,IF(Production!C16=":",0,Production!C16)+IF(Import!C16=":",0,Import!C16)-IF(Export!C16=":",0,Export!C16)) -> 90060700 | D13: =MAX(0,IF(Production!D16=":",0,Production!D16)+IF(Import!D16=":",0,Import!D16)-IF(Export!D16=":",0,Export!D16)) -> 87339700 | E13: =MAX(0,IF(Production!E16=":",0,Production!E16)+IF(Import!E16=":",0,Import!E16)-IF(Export!E16=":",0,Export!E16)) -> 92883100 | F13: =MAX(0,IF(Production!F16=":",0,Production!F16)+IF(Import!F16=":",0,Import!F16)-IF(Export!F16=":",0,Export!F16)) -> 81923000 | G13: =MAX(0,IF(Production!G16=":",0,Production!G16)+IF(Import!G16=":",0,Import!G16)-IF(Export!G16=":",0,Export!G16)) -> 78637600 | H13: =MAX(0,IF(Production!H16=":",0,Production!H16)+IF(Import!H16=":",0,Import!H16)-IF(Export!H16=":",0,Export!H16)) -> 89505226 | I13: =MAX(0,IF(Production!I16=":",0,Production!I16)+IF(Import!I16=":",0,Import!I16)-IF(Export!I16=":",0,Export!I16)) -> 95705901 | ... L13: =MAX(0,IF(Production!L16=":",0,Production!L16)+IF(Import!L16=":",0,Import!L16)-IF(Export!L16=":",0,Export!L16)) -> 58658563
A14: DE | B14: =MAX(0,IF(Production!B17=":",0,Production!B17)+IF(Import!B17=":",0,Import!B17)-IF(Export!B17=":",0,Export!B17)) -> 2253939600 | C14: =MAX(0,IF(Production!C17=":",0,Production!C17)+IF(Import!C17=":",0,Import!C17)-IF(Export!C17=":",0,Export!C17)) -> 1980017800 | D14: =MAX(0,IF(Production!D17=":",0,Production!D17)+IF(Import!D17=":",0,Import!D17)-IF(Export!D17=":",0,Export!D17)) -> 2053292100 | E14: =MAX(0,IF(Production!E17=":",0,Production!E17)+IF(Import!E17=":",0,Import!E17)-IF(Export!E17=":",0,Export!E17)) -> 2328810900 | F14: =MAX(0,IF(Production!F17=":",0,Production!F17)+IF(Import!F17=":",0,Import!F17)-IF(Export!F17=":",0,Export!F17)) -> 2342277200 | G14: =MAX(0,IF(Production!G17=":",0,Production!G17)+IF(Import!G17=":",0,Import!G17)-IF(Export!G17=":",0,Export!G17)) -> 2560745700 | H14: =MAX(0,IF(Production!H17=":",0,Production!H17)+IF(Import!H17=":",0,Import!H17)-IF(Export!H17=":",0,Export!H17)) -> 2588061315 | I14: =MAX(0,IF(Production!I17=":",0,Production!I17)+IF(Import!I17=":",0,Import!I17)-IF(Export!I17=":",0,Export!I17)) -> 2730400650 | ... L14: =MAX(0,IF(Production!L17=":",0,Production!L17)+IF(Import!L17=":",0,Import!L17)-IF(Export!L17=":",0,Export!L17)) -> 2571957959
A15: DK | B15: =MAX(0,IF(Production!B18=":",0,Production!B18)+IF(Import!B18=":",0,Import!B18)-IF(Export!B18=":",0,Export!B18)) -> 33255790 | C15: =MAX(0,IF(Production!C18=":",0,Production!C18)+IF(Import!C18=":",0,Import!C18)-IF(Export!C18=":",0,Export!C18)) -> 55781995 | D15: =MAX(0,IF(Production!D18=":",0,Production!D18)+IF(Import!D18=":",0,Import!D18)-IF(Export!D18=":",0,Export!D18)) -> 54370400 | E15: =MAX(0,IF(Production!E18=":",0,Production!E18)+IF(Import!E18=":",0,Import!E18)-IF(Export!E18=":",0,Export!E18)) -> 69061300 | F15: =MAX(0,IF(Production!F18=":",0,Production!F18)+IF(Import!F18=":",0,Import!F18)-IF(Export!F18=":",0,Export!F18)) -> 68053550 | G15: =MAX(0,IF(Production!G18=":",0,Production!G18)+IF(Import!G18=":",0,Import!G18)-IF(Export!G18=":",0,Export!G18)) -> 49249800 | H15: =MAX(0,IF(Production!H18=":",0,Production!H18)+IF(Import!H18=":",0,Import!H18)-IF(Export!H18=":",0,Export!H18)) -> 54378031 | I15: =MAX(0,IF(Production!I18=":",0,Production!I18)+IF(Import!I18=":",0,Import!I18)-IF(Export!I18=":",0,Export!I18)) -> 51124824 | ... L15: =MAX(0,IF(Production!L18=":",0,Production!L18)+IF(Import!L18=":",0,Import!L18)-IF(Export!L18=":",0,Export!L18)) -> 22715096
A16: EE | B16: =MAX(0,IF(Production!B19=":",0,Production!B19)+IF(Import!B19=":",0,Import!B19)-IF(Export!B19=":",0,Export!B19)) -> 3516500 | C16: =MAX(0,IF(Production!C19=":",0,Production!C19)+IF(Import!C19=":",0,Import!C19)-IF(Export!C19=":",0,Export!C19)) -> 3495200 | D16: =MAX(0,IF(Production!D19=":",0,Production!D19)+IF(Import!D19=":",0,Import!D19)-IF(Export!D19=":",0,Export!D19)) -> 4894800 | E16: =MAX(0,IF(Production!E19=":",0,Production!E19)+IF(Import!E19=":",0,Import!E19)-IF(Export!E19=":",0,Export!E19)) -> 4790600 | F16: =MAX(0,IF(Production!F19=":",0,Production!F19)+IF(Import!F19=":",0,Import!F19)-IF(Export!F19=":",0,Export!F19)) -> 3077300 | G16: =MAX(0,IF(Production!G19=":",0,Production!G19)+IF(Import!G19=":",0,Import!G19)-IF(Export!G19=":",0,Export!G19)) -> 3802000 | H16: =MAX(0,IF(Production!H19=":",0,Production!H19)+IF(Import!H19=":",0,Import!H19)-IF(Export!H19=":",0,Export!H19)) -> 2338939 | I16: =MAX(0,IF(Production!I19=":",0,Production!I19)+IF(Import!I19=":",0,Import!I19)-IF(Export!I19=":",0,Export!I19)) -> 3633944 | ... L16: =MAX(0,IF(Production!L19=":",0,Production!L19)+IF(Import!L19=":",0,Import!L19)-IF(Export!L19=":",0,Export!L19)) -> 2572655
A17: ES | B17: =MAX(0,IF(Production!B20=":",0,Production!B20)+IF(Import!B20=":",0,Import!B20)-IF(Export!B20=":",0,Export!B20)) -> 465106500 | C17: =MAX(0,IF(Production!C20=":",0,Production!C20)+IF(Import!C20=":",0,Import!C20)-IF(Export!C20=":",0,Export!C20)) -> 488305300 | D17: =MAX(0,IF(Production!D20=":",0,Production!D20)+IF(Import!D20=":",0,Import!D20)-IF(Export!D20=":",0,Export!D20)) -> 492582800 | E17: =MAX(0,IF(Production!E20=":",0,Production!E20)+IF(Import!E20=":",0,Import!E20)-IF(Export!E20=":",0,Export!E20)) -> 616593000 | F17: =MAX(0,IF(Production!F20=":",0,Production!F20)+IF(Import!F20=":",0,Import!F20)-IF(Export!F20=":",0,Export!F20)) -> 621696600 | G17: =MAX(0,IF(Production!G20=":",0,Production!G20)+IF(Import!G20=":",0,Import!G20)-IF(Export!G20=":",0,Export!G20)) -> 635499400 | H17: =MAX(0,IF(Production!H20=":",0,Production!H20)+IF(Import!H20=":",0,Import!H20)-IF(Export!H20=":",0,Export!H20)) -> 580266373 | I17: =MAX(0,IF(Production!I20=":",0,Production!I20)+IF(Import!I20=":",0,Import!I20)-IF(Export!I20=":",0,Export!I20)) -> 582521348 | ... L17: =MAX(0,IF(Production!L20=":",0,Production!L20)+IF(Import!L20=":",0,Import!L20)-IF(Export!L20=":",0,Export!L20)) -> 446799481
A18: FI | B18: =MAX(0,IF(Production!B21=":",0,Production!B21)+IF(Import!B21=":",0,Import!B21)-IF(Export!B21=":",0,Export!B21)) -> 135118600 | C18: =MAX(0,IF(Production!C21=":",0,Production!C21)+IF(Import!C21=":",0,Import!C21)-IF(Export!C21=":",0,Export!C21)) -> 141771700 | D18: =MAX(0,IF(Production!D21=":",0,Production!D21)+IF(Import!D21=":",0,Import!D21)-IF(Export!D21=":",0,Export!D21)) -> 150637200 | E18: =MAX(0,IF(Production!E21=":",0,Production!E21)+IF(Import!E21=":",0,Import!E21)-IF(Export!E21=":",0,Export!E21)) -> 132436900 | F18: =MAX(0,IF(Production!F21=":",0,Production!F21)+IF(Import!F21=":",0,Import!F21)-IF(Export!F21=":",0,Export!F21)) -> 120096600 | G18: =MAX(0,IF(Production!G21=":",0,Production!G21)+IF(Import!G21=":",0,Import!G21)-IF(Export!G21=":",0,Export!G21)) -> 145010300 | H18: =MAX(0,IF(Production!H21=":",0,Production!H21)+IF(Import!H21=":",0,Import!H21)-IF(Export!H21=":",0,Export!H21)) -> 109928674 | I18: =MAX(0,IF(Production!I21=":",0,Production!I21)+IF(Import!I21=":",0,Import!I21)-IF(Export!I21=":",0,Export!I21)) -> 120143976 | ... L18: =MAX(0,IF(Production!L21=":",0,Production!L21)+IF(Import!L21=":",0,Import!L21)-IF(Export!L21=":",0,Export!L21)) -> 39614436
A19: FR | B19: =MAX(0,IF(Production!B22=":",0,Production!B22)+IF(Import!B22=":",0,Import!B22)-IF(Export!B22=":",0,Export!B22)) -> 643122700 | C19: =MAX(0,IF(Production!C22=":",0,Production!C22)+IF(Import!C22=":",0,Import!C22)-IF(Export!C22=":",0,Export!C22)) -> 638793600 | D19: =MAX(0,IF(Production!D22=":",0,Production!D22)+IF(Import!D22=":",0,Import!D22)-IF(Export!D22=":",0,Export!D22)) -> 620774600 | E19: =MAX(0,IF(Production!E22=":",0,Production!E22)+IF(Import!E22=":",0,Import!E22)-IF(Export!E22=":",0,Export!E22)) -> 632939040 | F19: =MAX(0,IF(Production!F22=":",0,Production!F22)+IF(Import!F22=":",0,Import!F22)-IF(Export!F22=":",0,Export!F22)) -> 680327566 | G19: =MAX(0,IF(Production!G22=":",0,Production!G22)+IF(Import!G22=":",0,Import!G22)-IF(Export!G22=":",0,Export!G22)) -> 631418053 | H19: =MAX(0,IF(Production!H22=":",0,Production!H22)+IF(Import!H22=":",0,Import!H22)-IF(Export!H22=":",0,Export!H22)) -> 586590875 | I19: =MAX(0,IF(Production!I22=":",0,Production!I22)+IF(Import!I22=":",0,Import!I22)-IF(Export!I22=":",0,Export!I22)) -> 580279393 | ... L19: =MAX(0,IF(Production!L22=":",0,Production!L22)+IF(Import!L22=":",0,Import!L22)-IF(Export!L22=":",0,Export!L22)) -> 649541885
... A30: MK | B30: =MAX(0,IF(Production!B33=":",0,Production!B33)+IF(Import!B33=":",0,Import!B33)-IF(Export!B33=":",0,Export!B33)) -> 0 | C30: =MAX(0,IF(Production!C33=":",0,Production!C33)+IF(Import!C33=":",0,Import!C33)-IF(Export!C33=":",0,Export!C33)) -> 0 | D30: =MAX(0,IF(Production!D33=":",0,Production!D33)+IF(Import!D33=":",0,Import!D33)-IF(Export!D33=":",0,Export!D33)) -> 0 | E30: =MAX(0,IF(Production!E33=":",0,Production!E33)+IF(Import!E33=":",0,Import!E33)-IF(Export!E33=":",0,Export!E33)) -> 0 | F30: =MAX(0,IF(Production!F33=":",0,Production!F33)+IF(Import!F33=":",0,Import!F33)-IF(Export!F33=":",0,Export!F33)) -> 0 | G30: =MAX(0,IF(Production!G33=":",0,Production!G33)+IF(Import!G33=":",0,Import!G33)-IF(Export!G33=":",0,Export!G33)) -> 0 | H30: =MAX(0,IF(Production!H33=":",0,Production!H33)+IF(Import!H33=":",0,Import!H33)-IF(Export!H33=":",0,Export!H33)) -> 0 | I30: =MAX(0,IF(Production!I33=":",0,Production!I33)+IF(Import!I33=":",0,Import!I33)-IF(Export!I33=":",0,Export!I33)) -> 0 | ... L30: =MAX(0,IF(Production!L33=":",0,Production!L33)+IF(Import!L33=":",0,Import!L33)-IF(Export!L33=":",0,Export!L33)) -> 0
A31: NL | B31: =MAX(0,IF(Production!B35=":",0,Production!B35)+IF(Import!B35=":",0,Import!B35)-IF(Export!B35=":",0,Export!B35)) -> 39682200 | C31: =MAX(0,IF(Production!C35=":",0,Production!C35)+IF(Import!C35=":",0,Import!C35)-IF(Export!C35=":",0,Export!C35)) -> 533160900 | D31: =MAX(0,IF(Production!D35=":",0,Production!D35)+IF(Import!D35=":",0,Import!D35)-IF(Export!D35=":",0,Export!D35)) -> 3532400 | E31: =MAX(0,IF(Production!E35=":",0,Production!E35)+IF(Import!E35=":",0,Import!E35)-IF(Export!E35=":",0,Export!E35)) -> 0 | F31: =MAX(0,IF(Production!F35=":",0,Production!F35)+IF(Import!F35=":",0,Import!F35)-IF(Export!F35=":",0,Export!F35)) -> 296004400 | G31: =MAX(0,IF(Production!G35=":",0,Production!G35)+IF(Import!G35=":",0,Import!G35)-IF(Export!G35=":",0,Export!G35)) -> 531569600 | H31: =MAX(0,IF(Production!H35=":",0,Production!H35)+IF(Import!H35=":",0,Import!H35)-IF(Export!H35=":",0,Export!H35)) -> 0 | I31: =MAX(0,IF(Production!I35=":",0,Production!I35)+IF(Import!I35=":",0,Import!I35)-IF(Export!I35=":",0,Export!I35)) -> 510039594 | ... L31: =MAX(0,IF(Production!L35=":",0,Production!L35)+IF(Import!L35=":",0,Import!L35)-IF(Export!L35=":",0,Export!L35)) -> 1000512941
A32: NO | B32: =MAX(0,IF(Production!B36=":",0,Production!B36)+IF(Import!B36=":",0,Import!B36)-IF(Export!B36=":",0,Export!B36)) -> 0 | C32: =MAX(0,IF(Production!C36=":",0,Production!C36)+IF(Import!C36=":",0,Import!C36)-IF(Export!C36=":",0,Export!C36)) -> 0 | D32: =MAX(0,IF(Production!D36=":",0,Production!D36)+IF(Import!D36=":",0,Import!D36)-IF(Export!D36=":",0,Export!D36)) -> 0 | E32: =MAX(0,IF(Production!E36=":",0,Production!E36)+IF(Import!E36=":",0,Import!E36)-IF(Export!E36=":",0,Export!E36)) -> 0 | F32: =MAX(0,IF(Production!F36=":",0,Production!F36)+IF(Import!F36=":",0,Import!F36)-IF(Export!F36=":",0,Export!F36)) -> 0 | G32: =MAX(0,IF(Production!G36=":",0,Production!G36)+IF(Import!G36=":",0,Import!G36)-IF(Export!G36=":",0,Export!G36)) -> 0 | H32: =MAX(0,IF(Production!H36=":",0,Production!H36)+IF(Import!H36=":",0,Import!H36)-IF(Export!H36=":",0,Export!H36)) -> 0 | I32: =MAX(0,IF(Production!I36=":",0,Production!I36)+IF(Import!I36=":",0,Import!I36)-IF(Export!I36=":",0,Export!I36)) -> 0 | ... L32: =MAX(0,IF(Production!L36=":",0,Production!L36)+IF(Import!L36=":",0,Import!L36)-IF(Export!L36=":",0,Export!L36)) -> 0
A33: PL | B33: =MAX(0,IF(Production!B37=":",0,Production!B37)+IF(Import!B37=":",0,Import!B37)-IF(Export!B37=":",0,Export!B37)) -> 314005900 | C33: =MAX(0,IF(Production!C37=":",0,Production!C37)+IF(Import!C37=":",0,Import!C37)-IF(Export!C37=":",0,Export!C37)) -> 368531600 | D33: =MAX(0,IF(Production!D37=":",0,Production!D37)+IF(Import!D37=":",0,Import!D37)-IF(Export!D37=":",0,Export!D37)) -> 378829400 | E33: =MAX(0,IF(Production!E37=":",0,Production!E37)+IF(Import!E37=":",0,Import!E37)-IF(Export!E37=":",0,Export!E37)) -> 545917500 | F33: =MAX(0,IF(Production!F37=":",0,Production!F37)+IF(Import!F37=":",0,Import!F37)-IF(Export!F37=":",0,Export!F37)) -> 564781400 | G33: =MAX(0,IF(Production!G37=":",0,Production!G37)+IF(Import!G37=":",0,Import!G37)-IF(Export!G37=":",0,Export!G37)) -> 510531000 | H33: =MAX(0,IF(Production!H37=":",0,Production!H37)+IF(Import!H37=":",0,Import!H37)-IF(Export!H37=":",0,Export!H37)) -> 451732744 | I33: =MAX(0,IF(Production!I37=":",0,Production!I37)+IF(Import!I37=":",0,Import!I37)-IF(Export!I37=":",0,Export!I37)) -> 503372395 | ... L33: =MAX(0,IF(Production!L37=":",0,Production!L37)+IF(Import!L37=":",0,Import!L37)-IF(Export!L37=":",0,Export!L37)) -> 449013241
A34: PT | B34: =MAX(0,IF(Production!B38=":",0,Production!B38)+IF(Import!B38=":",0,Import!B38)-IF(Export!B38=":",0,Export!B38)) -> 142055600 | C34: =MAX(0,IF(Production!C38=":",0,Production!C38)+IF(Import!C38=":",0,Import!C38)-IF(Export!C38=":",0,Export!C38)) -> 131750900 | D34: =MAX(0,IF(Production!D38=":",0,Production!D38)+IF(Import!D38=":",0,Import!D38)-IF(Export!D38=":",0,Export!D38)) -> 135434000 | E34: =MAX(0,IF(Production!E38=":",0,Production!E38)+IF(Import!E38=":",0,Import!E38)-IF(Export!E38=":",0,Export!E38)) -> 138607500 | F34: =MAX(0,IF(Production!F38=":",0,Production!F38)+IF(Import!F38=":",0,Import!F38)-IF(Export!F38=":",0,Export!F38)) -> 149766600 | G34: =MAX(0,IF(Production!G38=":",0,Production!G38)+IF(Import!G38=":",0,Import!G38)-IF(Export!G38=":",0,Export!G38)) -> 140463200 | H34: =MAX(0,IF(Production!H38=":",0,Production!H38)+IF(Import!H38=":",0,Import!H38)-IF(Export!H38=":",0,Export!H38)) -> 141957493 | I34: =MAX(0,IF(Production!I38=":",0,Production!I38)+IF(Import!I38=":",0,Import!I38)-IF(Export!I38=":",0,Export!I38)) -> 167826587 | ... L34: =MAX(0,IF(Production!L38=":",0,Production!L38)+IF(Import!L38=":",0,Import!L38)-IF(Export!L38=":",0,Export!L38)) -> 124725463
A35: RO | B35: =MAX(0,IF(Production!B39=":",0,Production!B39)+IF(Import!B39=":",0,Import!B39)-IF(Export!B39=":",0,Export!B39)) -> 136899800 | C35: =MAX(0,IF(Production!C39=":",0,Production!C39)+IF(Import!C39=":",0,Import!C39)-IF(Export!C39=":",0,Export!C39)) -> 129601900 | D35: =MAX(0,IF(Production!D39=":",0,Production!D39)+IF(Import!D39=":",0,Import!D39)-IF(Export!D39=":",0,Export!D39)) -> 154294200 | E35: =MAX(0,IF(Production!E39=":",0,Production!E39)+IF(Import!E39=":",0,Import!E39)-IF(Export!E39=":",0,Export!E39)) -> 165867000 | F35: =MAX(0,IF(Production!F39=":",0,Production!F39)+IF(Import!F39=":",0,Import!F39)-IF(Export!F39=":",0,Export!F39)) -> 160452000 | G35: =MAX(0,IF(Production!G39=":",0,Production!G39)+IF(Import!G39=":",0,Import!G39)-IF(Export!G39=":",0,Export!G39)) -> 176406561 | H35: =MAX(0,IF(Production!H39=":",0,Production!H39)+IF(Import!H39=":",0,Import!H39)-IF(Export!H39=":",0,Export!H39)) -> 181218020 | I35: =MAX(0,IF(Production!I39=":",0,Production!I39)+IF(Import!I39=":",0,Import!I39)-IF(Export!I39=":",0,Export!I39)) -> 205061098 | ... L35: =MAX(0,IF(Production!L39=":",0,Production!L39)+IF(Import!L39=":",0,Import!L39)-IF(Export!L39=":",0,Export!L39)) -> 125623699
A36: SE | B36: =MAX(0,IF(Production!B40=":",0,Production!B40)+IF(Import!B40=":",0,Import!B40)-IF(Export!B40=":",0,Export!B40)) -> 186355600 | C36: =MAX(0,IF(Production!C40=":",0,Production!C40)+IF(Import!C40=":",0,Import!C40)-IF(Export!C40=":",0,Export!C40)) -> 198065600 | D36: =MAX(0,IF(Production!D40=":",0,Production!D40)+IF(Import!D40=":",0,Import!D40)-IF(Export!D40=":",0,Export!D40)) -> 174464400 | E36: =MAX(0,IF(Production!E40=":",0,Production!E40)+IF(Import!E40=":",0,Import!E40)-IF(Export!E40=":",0,Export!E40)) -> 200462900 | F36: =MAX(0,IF(Production!F40=":",0,Production!F40)+IF(Import!F40=":",0,Import!F40)-IF(Export!F40=":",0,Export!F40)) -> 209937100 | G36: =MAX(0,IF(Production!G40=":",0,Production!G40)+IF(Import!G40=":",0,Import!G40)-IF(Export!G40=":",0,Export!G40)) -> 219307000 | H36: =MAX(0,IF(Production!H40=":",0,Production!H40)+IF(Import!H40=":",0,Import!H40)-IF(Export!H40=":",0,Export!H40)) -> 197515153 | I36: =MAX(0,IF(Production!I40=":",0,Production!I40)+IF(Import!I40=":",0,Import!I40)-IF(Export!I40=":",0,Export!I40)) -> 198252601 | ... L36: =MAX(0,IF(Production!L40=":",0,Production!L40)+IF(Import!L40=":",0,Import!L40)-IF(Export!L40=":",0,Export!L40)) -> 76842804
A37: SI | B37: =MAX(0,IF(Production!B41=":",0,Production!B41)+IF(Import!B41=":",0,Import!B41)-IF(Export!B41=":",0,Export!B41)) -> 0 | C37: =MAX(0,IF(Production!C41=":",0,Production!C41)+IF(Import!C41=":",0,Import!C41)-IF(Export!C41=":",0,Export!C41)) -> 0 | D37: =MAX(0,IF(Production!D41=":",0,Production!D41)+IF(Import!D41=":",0,Import!D41)-IF(Export!D41=":",0,Export!D41)) -> 0 | E37: =MAX(0,IF(Production!E41=":",0,Production!E41)+IF(Import!E41=":",0,Import!E41)-IF(Export!E41=":",0,Export!E41)) -> 0 | F37: =MAX(0,IF(Production!F41=":",0,Production!F41)+IF(Import!F41=":",0,Import!F41)-IF(Export!F41=":",0,Export!F41)) -> 0 | G37: =MAX(0,IF(Production!G41=":",0,Production!G41)+IF(Import!G41=":",0,Import!G41)-IF(Export!G41=":",0,Export!G41)) -> 0 | H37: =MAX(0,IF(Production!H41=":",0,Production!H41)+IF(Import!H41=":",0,Import!H41)-IF(Export!H41=":",0,Export!H41)) -> 0 | I37: =MAX(0,IF(Production!I41=":",0,Production!I41)+IF(Import!I41=":",0,Import!I41)-IF(Export!I41=":",0,Export!I41)) -> 0 | ... L37: =MAX(0,IF(Production!L41=":",0,Production!L41)+IF(Import!L41=":",0,Import!L41)-IF(Export!L41=":",0,Export!L41)) -> 0
A38: SK | B38: =MAX(0,IF(Production!B42=":",0,Production!B42)+IF(Import!B42=":",0,Import!B42)-IF(Export!B42=":",0,Export!B42)) -> 48077400 | C38: =MAX(0,IF(Production!C42=":",0,Production!C42)+IF(Import!C42=":",0,Import!C42)-IF(Export!C42=":",0,Export!C42)) -> 46391800 | D38: =MAX(0,IF(Production!D42=":",0,Production!D42)+IF(Import!D42=":",0,Import!D42)-IF(Export!D42=":",0,Export!D42)) -> 34935800 | E38: =MAX(0,IF(Production!E42=":",0,Production!E42)+IF(Import!E42=":",0,Import!E42)-IF(Export!E42=":",0,Export!E42)) -> 33879300 | F38: =MAX(0,IF(Production!F42=":",0,Production!F42)+IF(Import!F42=":",0,Import!F42)-IF(Export!F42=":",0,Export!F42)) -> 26298300 | G38: =MAX(0,IF(Production!G42=":",0,Production!G42)+IF(Import!G42=":",0,Import!G42)-IF(Export!G42=":",0,Export!G42)) -> 40105200 | H38: =MAX(0,IF(Production!H42=":",0,Production!H42)+IF(Import!H42=":",0,Import!H42)-IF(Export!H42=":",0,Export!H42)) -> 27066106 | I38: =MAX(0,IF(Production!I42=":",0,Production!I42)+IF(Import!I42=":",0,Import!I42)-IF(Export!I42=":",0,Export!I42)) -> 48256601 | ... L38: =MAX(0,IF(Production!L42=":",0,Production!L42)+IF(Import!L42=":",0,Import!L42)-IF(Export!L42=":",0,Export!L42)) -> 49543190
A39: RS | B39: =MAX(0,IF(Production!B43=":",0,Production!B43)+IF(Import!B43=":",0,Import!B43)-IF(Export!B43=":",0,Export!B43)) -> 0 | C39: =MAX(0,IF(Production!C43=":",0,Production!C43)+IF(Import!C43=":",0,Import!C43)-IF(Export!C43=":",0,Export!C43)) -> 0 | D39: =MAX(0,IF(Production!D43=":",0,Production!D43)+IF(Import!D43=":",0,Import!D43)-IF(Export!D43=":",0,Export!D43)) -> 0 | E39: =MAX(0,IF(Production!E43=":",0,Production!E43)+IF(Import!E43=":",0,Import!E43)-IF(Export!E43=":",0,Export!E43)) -> 0 | F39: =MAX(0,IF(Production!F43=":",0,Production!F43)+IF(Import!F43=":",0,Import!F43)-IF(Export!F43=":",0,Export!F43)) -> 0 | G39: =MAX(0,IF(Production!G43=":",0,Production!G43)+IF(Import!G43=":",0,Import!G43)-IF(Export!G43=":",0,Export!G43)) -> 0 | H39: =MAX(0,IF(Production!H43=":",0,Production!H43)+IF(Import!H43=":",0,Import!H43)-IF(Export!H43=":",0,Export!H43)) -> 0 | I39: =MAX(0,IF(Production!I43=":",0,Production!I43)+IF(Import!I43=":",0,Import!I43)-IF(Export!I43=":",0,Export!I43)) -> 0 | ... L39: =MAX(0,IF(Production!L43=":",0,Production!L43)+IF(Import!L43=":",0,Import!L43)-IF(Export!L43=":",0,Export!L43)) -> 0
A41: Special value
A42: : | B42: not available

Sheet Production
A1: Data extracted on 20/12/2025 14:06:04 from [ESTAT]
A2: Dataset: | B2: Total production [ds-059359__custom_19409157]
A3: Last updated: | B3: 27/11/2025 11:00
A5: PRODUCT [PRODUCT] | C5: Methanol (methyl alcohol) [20142210]
A6: INDICATORS | C6: Actual production quantity
A8: TIME | B8: 2014 | C8: 2015 | D8: 2016 | E8: 2017 | F8: 2018 | G8: 2019 | H8: 2020 | I8: 2021 | J8: 2022 | K8: 2023 | L8: 2024
A9: FREQ (Labels) | B9: Annual | C9: Annual | D9: Annual | E9: Annual | F9: Annual | G9: Annual | H9: Annual | I9: Annual | J9: Annual | K9: Annual | L9: Annual
A10: REPORTER (Labels)
A11: Albania | B11: : | C11: : | D11: : | E11: : | F11: : | G11: : | H11: : | I11: : | J11: : | K11: 0 | L11: 0
A12: Austria | B12: 0 | C12: : | D12: : | E12: : | F12: 0 | G12: 0 | H12: 0 | I12: : | J12: : | K12: 0 | L12: :
A13: Bosnia and Herzegovina | B13: 0 | C13: 0 | D13: : | E13: 0 | F13: 0 | G13: 0 | H13: 0 | I13: : | J13: : | K13: 0 | L13: 0
A14: Belgium (incl. Luxembourg 'LU' -> 1998) | B14: 3249430 | C14: 3794588 | D14: 4591449 | E14: : | F14: 5480067 | G14: : | H14: : | I14: 7565985 | J14: : | K14: : | L14: :
A15: Bulgaria | B15: 0 | C15: 0 | D15: 0 | E15: 0 | F15: 0 | G15: 0 | H15: : | I15: : | J15: : | K15: 0 | L15: 0
A16: Czechia | B16: : | C16: : | D16: : | E16: : | F16: : | G16: : | H16: : | I16: : | J16: : | K16: : | L16: :
A17: Germany (incl. German Democratic Republic 'DD' from 1991) | B17: 993429000 | C17: 940824000 | D17: 1043776000 | E17: 1046777000 | F17: 1129557000 | G17: 1398146000 | H17: 1523239000 | I17: 1358942000 | J17: 1089413000 | K17: : | L17: 757097000
A18: Denmark | B18: 75890 | C18: 87795 | D18: : | E18: 203900 | F18: 251650 | G18: : | H18: : | I18: : | J18: : | K18: : | L18: :
A19: Estonia | B19: 0 | C19: 0 | D19: 0 | E19: 0 | F19: 0 | G19: 0 | H19: : | I19: : | J19: : | K19: 0 | L19: 0
A20: Spain (incl. Canary Islands 'XB' from 1997) | B20: 939000 | C20: 1248000 | D20: 1134000 | E20: 920000 | F20: 865000 | G20: 760000 | H20: 1139000 | I20: 1155000 | J20: 441000 | K20: 1008000 | L20: 1107000
A21: Finland | B21: 0 | C21: 0 | D21: 0 | E21: 0 | F21: 0 | G21: 0 | H21: 0 | I21: 0 | J21: 0 | K21: 0 | L21: 23677
A22: France (incl. Saint Barthélemy 'BL' -> 2012; incl. French Guiana 'GF', Guadeloupe 'GP', Martinique 'MQ', Réunion 'RE' from 1997; incl. Mayotte 'YT' from 2014) | B22: : | C22: : | D22: : | E22: 14303740 | F22: 13637166 | G22: 13162753 | H22: 10771816 | I22: 1908201 | J22: 9510126 | K22: 7516476 | L22: 9426231
A23: United Kingdom | B23: : | C23: : | D23: : | E23: : | F23: : | G23: : | H23: : | I23: : | J23: : | K23: : | L23: :
A24: Greece | B24: 0 | C24: 0 | D24: 0 | E24: 0 | F24: 0 | G24: 0 | H24: 0 | I24: 0 | J24: 0 | K24: 0 | L24: 0
A25: Croatia | B25: 943 | C25: 947 | D25: 883 | E25: 722 | F25: 1520 | G25: 1104 | H25: 0 | I25: 331 | J25: 871 | K25: 547 | L25: 442
A26: Hungary | B26: : | C26: 263000 | D26: : | E26: : | F26: 103000 | G26: : | H26: 206000 | I26: : | J26: : | K26: 2000 | L26: 11000
A27: Ireland (Eire) | B27: : | C27: : | D27: : | E27: 0 | F27: 0 | G27: 0 | H27: 0 | I27: : | J27: : | K27: 0 | L27: 0
A28: Italy (incl. San Marino 'SM' -> 1993) | B28: : | C28: : | D28: : | E28: : | F28: : | G28: : | H28: : | I28: : | J28: : | K28: : | L28: :
A29: Lithuania | B29: 0 | C29: 0 | D29: 0 | E29: 0 | F29: : | G29: 0 | H29: 0 | I29: : | J29: 0 | K29: 0 | L29: 0
A30: Luxembourg | B30: 0 | C30: 0 | D30: 0 | E30: 0 | F30: 0 | G30: 0 | H30: 0 | I30: 0 | J30: 0 | K30: 0 | L30: 0
A31: Latvia | B31: 0 | C31: 0 | D31: 0 | E31: 0 | F31: 0 | G31: 0 | H31: 0 | I31: : | J31: : | K31: 0 | L31: 0
A32: Montenegro | B32: 0 | C32: 0 | D32: 0 | E32: 0 | F32: 0 | G32: 0 | H32: 0 | I32: 0 | J32: : | K32: 0 | L32: 0
A33: North Macedonia | B33: 0 | C33: 0 | D33: 0 | E33: 0 | F33: 0 | G33: 0 | H33: 0 | I33: 0 | J33: 0 | K33: 0 | L33: 0
A34: Malta | B34: 0 | C34: 0 | D34: 0 | E34: 0 | F34: 0 | G34: 0 | H34: 0 | I34: 0 | J34: 0 | K34: 0 | L34: 0
A35: Netherlands | B35: : | C35: : | D35: 477340000 | E35: : | F35: : | G35: : | H35: : | I35: : | J35: : | K35: : | L35: :
A36: Norway (incl. Svalbard and Jan Mayen 'SJ' -> 1994 and again from 1997) | B36: : | C36: : | D36: : | E36: : | F36: : | G36: : | H36: : | I36: : | J36: : | K36: 0 | L36: 0
A37: Poland | B37: : | C37: : | D37: : | E37: : | F37: : | G37: 0 | H37: : | I37: : | J37: : | K37: : | L37: :
A38: Portugal | B38: 0 | C38: 0 | D38: 0 | E38: 0 | F38: 0 | G38: 0 | H38: 0 | I38: : | J38: : | K38: 0 | L38: 0
A39: Romania | B39: : | C39: 0 | D39: 0 | E39: 0 | F39: 0 | G39: 10061 | H39: : | I39: 0 | J39: 0 | K39: 0 | L39: 0
A40: Sweden | B40: 0 | C40: 0 | D40: 0 | E40: 0 | F40: 0 | G40: 0 | H40: 0 | I40: 3277000 | J40: 3019000 | K40: 2667000 | L40: :
A41: Slovenia | B41: 0 | C41: 0 | D41: 0 | E41: 0 | F41: 0 | G41: 0 | H41: 0 | I41: 0 | J41: 0 | K41: 0 | L41: 0
A42: Slovakia | B42: 0 | C42: 0 | D42: 0 | E42: 0 | F42: 0 | G42: 0 | H42: 0 | I42: 0 | J42: 0 | K42: 0 | L42: 0
...

Sheet Export
A1: Data extracted on 20/12/2025 13:44:03 from [ESTAT]
A2: Dataset: | B2: Sold production, exports and imports [ds-059358__custom_19409073]
A3: Last updated: | B3: 02/12/2025 11:00
A5: PRODUCT [PRODUCT] | C5: Methanol (methyl alcohol) [20142210]
A6: INDICATORS | C6: Exports quantity
A8: TIME | B8: 2014 | C8: 2015 | D8: 2016 | E8: 2017 | F8: 2018 | G8: 2019 | H8: 2020 | I8: 2021 | J8: 2022 | K8: 2023 | L8: 2024
A9: FREQ (Labels) | B9: Annual | C9: Annual | D9: Annual | E9: Annual | F9: Annual | G9: Annual | H9: Annual | I9: Annual | J9: Annual | K9: Annual | L9: Annual
A10: REPORTER (Labels)
A11: Albania | B11: : | C11: : | D11: : | E11: : | F11: : | G11: : | H11: : | I11: : | J11: : | K11: : | L11: :
A12: Austria | B12: 1358500 | C12: 3214400 | D12: 1235900 | E12: 1627900 | F12: 954100 | G12: 646700 | H12: 3575933 | I12: 3901316 | J12: 3355351 | K12: 2735143 | L12: 1446241
A13: Bosnia and Herzegovina | B13: : | C13: : | D13: : | E13: : | F13: : | G13: : | H13: : | I13: : | J13: : | K13: : | L13: :
A14: Belgium (incl. Luxembourg 'LU' -> 1998) | B14: 262437600 | C14: 260184900 | D14: 261940600 | E14: 198470900 | F14: 209909800 | G14: 220041700 | H14: 314030909 | I14: 384118153 | J14: 355054250 | K14: 569969502 | L14: 843805292
A15: Bulgaria | B15: 7667200 | C15: 5049700 | D15: 3036800 | E15: 1476600 | F15: 700300 | G15: 1441600 | H15: 1171492 | I15: 740852 | J15: 396191 | K15: 1145378 | L15: 1034556
A16: Czechia | B16: 1721300 | C16: 1259200 | D16: 2308800 | E16: 3998500 | F16: 4041200 | G16: 1644900 | H16: 787296 | I16: 230026 | J16: 4299579 | K16: 6048040 | L16: 7484183
A17: Germany (incl. German Democratic Republic 'DD' from 1991) | B17: 319136000 | C17: 300648500 | D17: 312225100 | E17: 255450700 | F17: 255533700 | G17: 217703100 | H17: 267288885 | I17: 229290688 | J17: 211090192 | K17: 183068967 | L17: 149405282
A18: Denmark | B18: 51200 | C18: 585000 | D18: 1306400 | E18: 887000 | F18: 1052700 | G18: 1020300 | H18: 1139892 | I18: 1254477 | J18: 3671513 | K18: 1573758 | L18: 3291327
A19: Estonia | B19: 978200 | C19: 1594700 | D19: 1977800 | E19: 2092000 | F19: 1733400 | G19: 94800 | H19: 57988 | I19: 727 | J19: 1906 | K19: 5960657 | L19: 213773
A20: Spain (incl. Canary Islands 'XB' from 1997) | B20: 66319800 | C20: 39965900 | D20: 53428000 | E20: 35833500 | F20: 39634400 | G20: 42958300 | H20: 41075607 | I20: 37536532 | J20: 48779645 | K20: 32356218 | L20: 49886279
A21: Finland | B21: 358122900 | C21: 277447000 | D21: 217893400 | E21: 252904100 | F21: 180425400 | G21: 213490900 | H21: 187958281 | I21: 142718024 | J21: 144397166 | K21: 6088121 | L21: 5105016
A22: France (incl. Saint Barthélemy 'BL' -> 2012; incl. French Guiana 'GF', Guadeloupe 'GP', Martinique 'MQ', Réunion 'RE' from 1997; incl. Mayotte 'YT' from 2014) | B22: 22194700 | C22: 3380500 | D22: 5393600 | E22: 6919700 | F22: 2964600 | G22: 3032600 | H22: 2631182 | I22: 2731504 | J22: 2559616 | K22: 1386123 | L22: 1671499
A23: United Kingdom | B23: 7268400 | C23: 7570300 | D23: 7326400 | E23: 5971900 | F23: 5843800 | G23: 6421100 | H23: : | I23: : | J23: : | K23: : | L23: :
A24: Greece | B24: 24300 | C24: 100 | D24: 1100 | E24: 49100 | F24: 0 | G24: 28300 | H24: 975629 | I24: 1510 | J24: 128 | K24: 40672 | L24: 48015
A25: Croatia | B25: 99900 | C25: 80500 | D25: 95000 | E25: 236000 | F25: 38200 | G25: 35200 | H25: 29908 | I25: 21023 | J25: 57521 | K25: 26457 | L25: 8646
A26: Hungary | B26: 3597000 | C26: 2240200 | D26: 2823200 | E26: 1026000 | F26: 267500 | G26: 58700 | H26: 201625 | I26: 298208 | J26: 1047643 | K26: 22460 | L26: 57078
A27: Ireland (Eire) | B27: 183700 | C27: 233800 | D27: 142100 | E27: 222600 | F27: 201500 | G27: 244500 | H27: 28543 | I27: 10220 | J27: 45139 | K27: 57547 | L27: 70033
A28: Italy (incl. San Marino 'SM' -> 1993) | B28: 11673900 | C28: 47478800 | D28: 49420800 | E28: 50422700 | F28: 13894800 | G28: 5827000 | H28: 5273145 | I28: 7074129 | J28: 11726863 | K28: 19226194 | L28: 13433637
A29: Lithuania | B29: 2256900 | C29: 745700 | D29: 2163600 | E29: 12548100 | F29: 20784000 | G29: 45304900 | H29: 25573540 | I29: 24003537 | J29: 14812411 | K29: 20768017 | L29: 28024446
A30: Luxembourg | B30: 10945200 | C30: 12601100 | D30: 11149500 | E30: 11197100 | F30: 10628000 | G30: 9580800 | H30: 9587181 | I30: 11513455 | J30: 11629766 | K30: 2795331 | L30: 2873468
A31: Latvia | B31: 8588000 | C31: 15032700 | D31: 21177400 | E31: 353500 | F31: 200 | G31: 118000 | H31: 171742 | I31: 197755 | J31: 6501087 | K31: 849269 | L31: 1614827
A32: Montenegro | B32: : | C32: : | D32: : | E32: : | F32: : | G32: : | H32: : | I32: : | J32: : | K32: : | L32: :
A33: North Macedonia | B33: : | C33: : | D33: : | E33: : | F33: : | G33: : | H33: : | I33: : | J33: : | K33: : | L33: :
A34: Malta | B34: 0 | C34: 0 | D34: 16900 | E34: 0 | F34: 0 | G34: 0 | H34: 51 | I34: 1 | J34: 35 | K34: 260 | L34: 1
A35: Netherlands | B35: 2570708900 | C35: 1935579800 | D35: 2129621400 | E35: 2284572200 | F35: 2178139600 | G35: 2214482600 | H35: 2042910673 | I35: 2041737390 | J35: 1507444093 | K35: 1890085397 | L35: 2539049504
A36: Norway (incl. Svalbard and Jan Mayen 'SJ' -> 1994 and again from 1997) | B36: : | C36: : | D36: : | E36: : | F36: : | G36: : | H36: : | I36: : | J36: : | K36: : | L36: :
A37: Poland | B37: 67342300 | C37: 79224400 | D37: 82369500 | E37: 98980400 | F37: 184032000 | G37: 143782300 | H37: 225723934 | I37: 192468594 | J37: 457455936 | K37: 264046966 | L37: 215770273
A38: Portugal | B38: 3253200 | C38: 6787500 | D38: 12864200 | E38: 15608000 | F38: 16558400 | G38: 16184800 | H38: 17092775 | I38: 16861434 | J38: 14897773 | K38: 8884275 | L38: 9902775
A39: Romania | B39: 9766500 | C39: 9548400 | D39: 1143400 | E39: 4476800 | F39: 2647200 | G39: 19268100 | H39: 23771061 | I39: 25938091 | J39: 43248576 | K39: 53622344 | L39: 59264845
A40: Sweden | B40: 451900 | C40: 195900 | D40: 966100 | E40: 5783000 | F40: 2007400 | G40: 1883900 | H40: 2386543 | I40: 2752210 | J40: 3368104 | K40: 2850735 | L40: 4029751
A41: Slovenia | B41: 0 | C41: 0 | D41: 0 | E41: 0 | F41: 0 | G41: 0 | H41: 0 | I41: 0 | J41: 0 | K41: 0 | L41: 0
A42: Slovakia | B42: 71804300 | C42: 69661000 | D42: 77952600 | E42: 66740600 | F42: 79926000 | G42: 58717200 | H42: 76245520 | I42: 74385010 | J42: 14044682 | K42: 27893 | L42: 2222
...

Sheet Import
A1: Data extracted on 20/12/2025 13:44:03 from [ESTAT]
A2: Dataset: | B2: Sold production, exports and imports [ds-059358__custom_19409073]
A3: Last updated: | B3: 02/12/2025 11:00
A5: PRODUCT [PRODUCT] | C5: Methanol (methyl alcohol) [20142210]
A6: INDICATORS | C6: Imports quantity
A8: TIME | B8: 2014 | C8: 2015 | D8: 2016 | E8: 2017 | F8: 2018 | G8: 2019 | H8: 2020 | I8: 2021 | J8: 2022 | K8: 2023 | L8: 2024
A9: FREQ (Labels) | B9: Annual | C9: Annual | D9: Annual | E9: Annual | F9: Annual | G9: Annual | H9: Annual | I9: Annual | J9: Annual | K9: Annual | L9: Annual
A10: REPORTER (Labels)
A11: Albania | B11: : | C11: : | D11: : | E11: : | F11: : | G11: : | H11: : | I11: : | J11: : | K11: : | L11: :
A12: Austria | B12: 189732700 | C12: 233185800 | D12: 258784300 | E12: 228127000 | F12: 254029200 | G12: 231239600 | H12: 206718140 | I12: 279470205 | J12: 215753076 | K12: 168448111 | L12: 140182588
A13: Bosnia and Herzegovina | B13: : | C13: : | D13: : | E13: : | F13: : | G13: : | H13: : | I13: : | J13: : | K13: : | L13: :
A14: Belgium (incl. Luxembourg 'LU' -> 1998) | B14: 814461800 | C14: 744444400 | D14: 791006000 | E14: 737025500 | F14: 798206800 | G14: 733706500 | H14: 866398402 | I14: 1067945015 | J14: 974040511 | K14: 1092585707 | L14: 1336222776
A15: Bulgaria | B15: 33982300 | C15: 34621200 | D15: 29178500 | E15: 26222100 | F15: 38601500 | G15: 42722700 | H15: 37638717 | I15: 39398723 | J15: 59933402 | K15: 53012760 | L15: 67087599
A16: Czechia | B16: 99782100 | C16: 91319900 | D16: 89648500 | E16: 96881600 | F16: 85964200 | G16: 80282500 | H16: 90292522 | I16: 95935927 | J16: 79204416 | K16: 76565047 | L16: 66142746
A17: Germany (incl. German Democratic Republic 'DD' from 1991) | B17: 1579646600 | C17: 1339842300 | D17: 1321741200 | E17: 1537484600 | F17: 1468253900 | G17: 1380302800 | H17: 1332111200 | I17: 1600749338 | J17: 1496840003 | K17: 1710712533 | L17: 1964266241
A18: Denmark | B18: 33231100 | C18: 56279200 | D18: 55676800 | E18: 69744400 | F18: 68854600 | G18: 50270100 | H18: 55517923 | I18: 52379301 | J18: 43538990 | K18: 40007251 | L18: 26006423
A19: Estonia | B19: 4494700 | C19: 5089900 | D19: 6872600 | E19: 6882600 | F19: 4810700 | G19: 3896800 | H19: 2396927 | I19: 3634671 | J19: 9865020 | K19: 11828890 | L19: 2786428
A20: Spain (incl. Canary Islands 'XB' from 1997) | B20: 530487300 | C20: 527023200 | D20: 544876800 | E20: 651506500 | F20: 660466000 | G20: 677697700 | H20: 620202980 | I20: 618902880 | J20: 594028850 | K20: 484455158 | L20: 495578760
A21: Finland | B21: 493241500 | C21: 419218700 | D21: 368530600 | E21: 385341000 | F21: 300522000 | G21: 358501200 | H21: 297886955 | I21: 262862000 | J21: 253618840 | K21: 74920610 | L21: 44695775
A22: France (incl. Saint Barthélemy 'BL' -> 2012; incl. French Guiana 'GF', Guadeloupe 'GP', Martinique 'MQ', Réunion 'RE' from 1997; incl. Mayotte 'YT' from 2014) | B22: 665317400 | C22: 642174100 | D22: 626168200 | E22: 625555000 | F22: 669655000 | G22: 621287900 | H22: 578450241 | I22: 581102696 | J22: 576113848 | K22: 534973280 | L22: 641787153
A23: United Kingdom | B23: 860187300 | C23: 931216900 | D23: 938241700 | E23: 859566500 | F23: 874217800 | G23: 649893400 | H23: : | I23: : | J23: : | K23: : | L23: :
A24: Greece | B24: 99767600 | C24: 88415300 | D24: 170383100 | E24: 190313400 | F24: 169280500 | G24: 151373200 | H24: 36953294 | I24: 38764580 | J24: 40203192 | K24: 40313207 | L24: 43889258
A25: Croatia | B25: 5857300 | C25: 4392200 | D25: 1787200 | E25: 1286500 | F25: 1369400 | G25: 1230600 | H25: 1187143 | I25: 1354118 | J25: 1540922 | K25: 1645235 | L25: 1513848
A26: Hungary | B26: 82028900 | C26: 95347200 | D26: 92327200 | E26: 101197300 | F26: 111987400 | G26: 113048300 | H26: 100257209 | I26: 110877097 | J26: 70701591 | K26: 90195441 | L26: 97547934
A27: Ireland (Eire) | B27: 26083300 | C27: 23938000 | D27: 29529000 | E27: 27186800 | F27: 29003100 | G27: 37984200 | H27: 36621396 | I27: 33443110 | J27: 38330500 | K27: 35584501 | L27: 42182195
A28: Italy (incl. San Marino 'SM' -> 1993) | B28: 553614500 | C28: 538543400 | D28: 548973700 | E28: 623406100 | F28: 592168500 | G28: 525916900 | H28: 441243104 | I28: 510581831 | J28: 492195700 | K28: 420351769 | L28: 388782359
A29: Lithuania | B29: 61873400 | C29: 62174000 | D29: 62460800 | E29: 78016100 | F29: 96823900 | G29: 119683700 | H29: 89785305 | I29: 102905462 | J29: 85625182 | K29: 76662640 | L29: 95460672
A30: Luxembourg | B30: 1975100 | C30: 1861200 | D30: 2528500 | E30: 1448800 | F30: 1080400 | G30: 1193700 | H30: 1093998 | I30: 1481330 | J30: 1310661 | K30: 1668556 | L30: 1466421
A31: Latvia | B31: 18111600 | C31: 28791300 | D31: 29974200 | E31: 12183100 | F31: 20020000 | G31: 20386600 | H31: 12026972 | I31: 9487618 | J31: 14461878 | K31: 6444609 | L31: 17305019
A32: Montenegro | B32: : | C32: : | D32: : | E32: : | F32: : | G32: : | H32: : | I32: : | J32: : | K32: : | L32: :
A33: North Macedonia | B33: : | C33: : | D33: : | E33: : | F33: : | G33: : | H33: : | I33: : | J33: : | K33: : | L33: :
A34: Malta | B34: 224500 | C34: 232800 | D34: 251000 | E34: 76900 | F34: 105900 | G34: 57900 | H34: 153086 | I34: 48218 | J34: 125129 | K34: 162541 | L34: 56131
A35: Netherlands | B35: 2610391100 | C35: 2468740700 | D35: 1655813800 | E35: 1585833500 | F35: 2474144000 | G35: 2746052200 | H35: 1694530939 | I35: 2551776984 | J35: 2443446888 | K35: 3222517774 | L35: 3539562445
A36: Norway (incl. Svalbard and Jan Mayen 'SJ' -> 1994 and again from 1997) | B36: : | C36: : | D36: : | E36: : | F36: : | G36: : | H36: : | I36: : | J36: : | K36: : | L36: :
A37: Poland | B37: 381348200 | C37: 447756000 | D37: 461198900 | E37: 644897900 | F37: 748813400 | G37: 654313300 | H37: 677456678 | I37: 695840989 | J37: 941995994 | K37: 637652649 | L37: 664783514
A38: Portugal | B38: 145308800 | C38: 138538400 | D38: 148298200 | E38: 154215500 | F38: 166325000 | G38: 156648000 | H38: 159050268 | I38: 184688021 | J38: 160622590 | K38: 165940611 | L38: 134628238
A39: Romania | B39: 146666300 | C39: 139150300 | D39: 155437600 | E39: 170343800 | F39: 163099200 | G39: 195664600 | H39: 204989081 | I39: 230999189 | J39: 239806627 | K39: 220643510 | L39: 184888544
A40: Sweden | B40: 186807500 | C40: 198261500 | D40: 175430500 | E40: 206245900 | F40: 211944500 | G40: 221190900 | H40: 199901696 | I40: 197727811 | J40: 142286449 | K40: 130137988 | L40: 80872555
A41: Slovenia | B41: 0 | C41: 0 | D41: 0 | E41: 0 | F41: 0 | G41: 0 | H41: 0 | I41: 0 | J41: 0 | K41: 0 | L41: 0
A42: Slovakia | B42: 119881700 | C42: 116052800 | D42: 112888400 | E42: 100619900 | F42: 106224300 | G42: 98822400 | H42: 103311626 | I42: 122641611 | J42: 74555265 | K42: 52512011 | L42: 49545412
...

Sheet Unit
A1: Data extracted on 20/12/2025 14:06:04 from [ESTAT]
A2: Dataset: | B2: Total production [ds-059359__custom_19409157]
A3: Last updated: | B3: 27/11/2025 11:00
A5: PRODUCT [PRODUCT] | C5: Methanol (methyl alcohol) [20142210]
A6: INDICATORS | C6: Quantity unit
A8: TIME | B8: 2014 | C8: 2015 | D8: 2016 | E8: 2017 | F8: 2018 | G8: 2019 | H8: 2020 | I8: 2021 | J8: 2022 | K8: 2023 | L8: 2024
A9: FREQ (Labels) | B9: Annual | C9: Annual | D9: Annual | E9: Annual | F9: Annual | G9: Annual | H9: Annual | I9: Annual | J9: Annual | K9: Annual | L9: Annual
A10: REPORTER (Labels)
A11: Albania | B11: : | C11: : | D11: : | E11: : | F11: : | G11: : | H11: : | I11: : | J11: KG | K11: KG | L11: KG
A12: Austria | B12: KG | C12: KG | D12: KG | E12: KG | F12: KG | G12: KG | H12: KG | I12: KG | J12: KG | K12: KG | L12: KG
A13: Bosnia and Herzegovina | B13: KG | C13: KG | D13: KG | E13: KG | F13: KG | G13: KG | H13: KG | I13: KG | J13: KG | K13: KG | L13: KG
A14: Belgium (incl. Luxembourg 'LU' -> 1998) | B14: KG | C14: KG | D14: KG | E14: KG | F14: KG | G14: KG | H14: KG | I14: KG | J14: KG | K14: KG | L14: KG
A15: Bulgaria | B15: KG | C15: KG | D15: KG | E15: KG | F15: KG | G15: KG | H15: KG | I15: KG | J15: KG | K15: KG | L15: KG
A16: Czechia | B16: KG | C16: KG | D16: KG | E16: KG | F16: KG | G16: KG | H16: KG | I16: KG | J16: KG | K16: KG | L16: KG
A17: Germany (incl. German Democratic Republic 'DD' from 1991) | B17: KG | C17: KG | D17: KG | E17: KG | F17: KG | G17: KG | H17: KG | I17: KG | J17: KG | K17: KG | L17: KG
A18: Denmark | B18: KG | C18: KG | D18: KG | E18: KG | F18: KG | G18: KG | H18: KG | I18: KG | J18: KG | K18: KG | L18: KG
A19: Estonia | B19: KG | C19: KG | D19: KG | E19: KG | F19: KG | G19: KG | H19: KG | I19: KG | J19: KG | K19: KG | L19: KG
A20: Spain (incl. Canary Islands 'XB' from 1997) | B20: KG | C20: KG | D20: KG | E20: KG | F20: KG | G20: KG | H20: KG | I20: KG | J20: KG | K20: KG | L20: KG
A21: Finland | B21: KG | C21: KG | D21: KG | E21: KG | F21: KG | G21: KG | H21: KG | I21: KG | J21: KG | K21: KG | L21: KG
A22: France (incl. Saint Barthélemy 'BL' -> 2012; incl. French Guiana 'GF', Guadeloupe 'GP', Martinique 'MQ', Réunion 'RE' from 1997; incl. Mayotte 'YT' from 2014) | B22: KG | C22: KG | D22: KG | E22: KG | F22: KG | G22: KG | H22: KG | I22: KG | J22: KG | K22: KG | L22: KG
... A43: Serbia | B43: KG | C43: KG | D43: KG | E43: KG | F43: KG | G43: KG | H43: KG | I43: KG | J43: KG | K43: KG | L43: KG
A45: Special value
A46: : | B46: not available
